<?xml version="1.0"?>
<robot xmlns:xacro="http://www.ros.org/wiki/xacro" name="r2d2">

  <!-- Parametrização -->
  <xacro:property name="cylinder_radius" value="0.1"/>
  <xacro:property name="cylinder_length" value="0.3"/>
  <xacro:property name="base_length" value="0.33"/>
  <xacro:property name="base_width"  value="0.05"/>
  <xacro:property name="base_height" value="0.03"/>
  <xacro:property name="sphere_radius" value="0.1"/>
  <xacro:property name="wheel_radius" value="0.06"/>
  <xacro:property name="wheel_length" value="0.04"/>
  
  <!-- Materiais -->
  <material name="blue">
    <color rgba="0 0 1 1"/>
  </material>

  <material name="white">
    <color rgba="1 1 1 1"/>
  </material>

  <material name="black">
    <color rgba="0 0 0 1"/>
  </material>

  <!-- Definição de algumas propriedades inerciais -->
  <xacro:macro name="box_inertia" params="m w h d">
    <inertial>
      <origin xyz="0 0 0" rpy="${pi/2} 0 ${pi/2}"/>
      <mass value="${m}"/>
      <inertia ixx="${(m/12) * (h*h + d*d)}" ixy="0.0" ixz="0.0" iyy="${(m/12) * (w*w + d*d)}" iyz="0.0" izz="${(m/12) * (w*w + h*h)}"/>
    </inertial>
  </xacro:macro>

  <xacro:macro name="cylinder_inertia" params="m r h">
    <inertial>
      <origin xyz="0 0 0" rpy="${pi/2} 0 0" />
      <mass value="${m}"/>
      <inertia ixx="${(m/12) * (3*r*r + h*h)}" ixy = "0" ixz = "0" iyy="${(m/12) * (3*r*r + h*h)}" iyz = "0" izz="${(m/2) * (r*r)}"/>
    </inertial>
  </xacro:macro>

  <xacro:macro name="sphere_inertia" params="m r">
    <inertial>
      <mass value="${m}"/>
      <inertia ixx="${(2/5) * m * (r*r)}" ixy="0.0" ixz="0.0" iyy="${(2/5) * m * (r*r)}" iyz="0.0" izz="${(2/5) * m * (r*r)}"/>
    </inertial>
  </xacro:macro>


  <!-- Link base -->
  <link name="base_link">
    <visual>
      <geometry>
        <cylinder radius="${cylinder_radius}" length="${cylinder_length}"/>
      </geometry>
      <origin xyz="0 0 0" rpy="0.5 0 0"/>
      <material name="white"/>
    </visual>
    <collision>
      <geometry>
        <cylinder radius="${cylinder_radius}" length="${cylinder_length}"/>
      </geometry>
      <origin xyz="0 0 0" rpy="0.5 0 0"/>
    </collision>
    
    <xacro:cylinder_inertia m="10" r="${cylinder_radius}" h="${cylinder_length}"/>

  </link>

  <!-- Função para criar pernas -->
  <xacro:macro name="leg_link" params="name pos">
    <link name="${name}">
      <visual>
        <geometry>
          <box size="${base_length} ${base_width} ${base_height}"/>
        </geometry>
        <origin xyz="0 0 0" rpy="0 1.58 0"/>
        <material name="blue"/>
      </visual>
      <collision>
        <geometry>
          <box size="${base_length} ${base_width} ${base_height}"/>
        </geometry>
          <origin xyz="0 0 0" rpy="0 1.58 0"/>
      </collision>
      
      <xacro:box_inertia m="1" w="${base_width}" d="${base_length}" h="${base_height}"/>
      
    </link>
    
    <joint name="base_to_${name}" type="fixed">
      <parent link="base_link"/>
      <child link="${name}"/>
      <origin xyz="${pos}" />
    </joint>
  </xacro:macro>
  

  <xacro:leg_link name="right_leg" pos="0.113 -0.05 -0.04"/>
  <xacro:leg_link name="left_leg" pos="-0.113 -0.05 -0.04"/>


  <!-- Cabeça -->
  <link name="head">
    <visual>
      <geometry>
        <sphere radius="${sphere_radius}"/>
      </geometry>
      <origin xyz="0.0 0.0 0.01" rpy="0 0 0"/>
      <material name="blue"/>
    </visual>
    <collision>
      <geometry>
        <sphere radius="${sphere_radius}"/>
      </geometry>
      <origin xyz="0.0 0.0 0.01" rpy="0 0 0"/>
    </collision>
    
    <xacro:sphere_inertia m="2" r="${sphere_radius}"/>

  </link>
  <joint name="base_to_head" type="fixed">
    <parent link="base_link"/>
    <child link="head"/>
    <axis xyz="0 0 1"/>
    <origin xyz="0.0 -0.0765 0.14"/>
  </joint>

  <!-- Base inferior -->
  <link name="base_bottom">
    <visual>
      <geometry>
        <box size="0.1 0.1 0.06"/>
      </geometry>
      <origin xyz="0 0 0" rpy="0.5 0 0"/>
      <material name="white"/>
    </visual>
    <collision>
      <geometry>
        <box size="0.1 0.1 0.06"/>
      </geometry>
      <origin xyz="0 0 0" rpy="0.5 0 0"/>
    </collision>

    <xacro:box_inertia m="10" w="0.1" h="0.1" d="0.06"/>

  </link>
  <joint name="base_to_base_bottom" type="fixed">
    <parent link="base_link"/>
    <child link="base_bottom"/>
    <origin xyz="0 0.07 -0.16"/>
  </joint>

  <!-- Função para rodas -->
  <xacro:macro name="wheel" params="name parent_link pos type">
    <link name="${name}">
      <visual>
        <origin xyz="0 0 0" rpy="0 ${pi/2} 0"/>
        <geometry>
          <cylinder radius="${wheel_radius}" length="${wheel_length}"/>
        </geometry>
        <material name="black"/>
      </visual>
      
      <collision>
        <origin xyz="0 0 0" rpy="0 ${pi/2} 0"/>
        <geometry>
          <cylinder radius="${wheel_radius}" length="${wheel_length}"/>
        </geometry>
      </collision>
      
      <xacro:cylinder_inertia m="2.5" r="${wheel_radius}" h="${wheel_length}"/>

    </link>
    <joint name="${parent_link}_to_${name}" type="${type}">
      <parent link="${parent_link}"/>
      <child link="${name}"/>
      <origin xyz="${pos}"/>
      <axis xyz="-1 0 0"/>
      <dynamics damping="0.2"/>
    </joint>

  </xacro:macro>

  <xacro:wheel name="wheel_front_left" parent_link="base_link" pos="-0.073 0.1 -0.2" type = "continuous"/>
  <xacro:wheel name="wheel_front_right" parent_link="base_link" pos="0.073 0.1 -0.2" type = "continuous"/>
  <xacro:wheel name="wheel_back_right" parent_link="base_link" pos="0.15 -0.05 -0.2" type = "continuous"/>
  <xacro:wheel name="wheel_back_left" parent_link="base_link" pos="-0.15 -0.05 -0.2" type = "continuous"/>

  <!-- Garra -->

  <link name="gripper_pole">
    <visual>
      <geometry>
        <cylinder length="0.2" radius="0.01"/>
      </geometry>
      <origin rpy="0 0 0" xyz="0 0 -0.1"/>
      <material name="blue"/>
    </visual>
    <collision>
      <geometry>
        <cylinder length="0.2" radius="0.01"/>
      </geometry>
      <origin rpy="0 0 0" xyz="0 0 -0.1"/>
    </collision>
    <xacro:cylinder_inertia m="0.01" r="0.01" h="0.2"/>
  </link>
  
  <joint name="gripper_extension" type="revolute">
    <axis xyz="-1 0 0"/>
    <limit effort="50.0" lower="-1.57075" upper="0.35" velocity="0.5"/>
    <origin rpy="${pi/2} 0 0" xyz="0 0.01 0.15"/>
    <parent link="base_link"/>
    <child link="gripper_pole"/>
  </joint>

  <link name="left_gripper">
    <visual>
      <geometry>
        <box size="0.1 0.02 0.02"/> <!-- Comprimento, largura, altura -->
      </geometry>
      <origin rpy="0 0 0" xyz="0 0 0"/>
      <material name="black"/>
    </visual>
    <collision>
      <geometry>
        <box size="0.1 0.02 0.02"/>
      </geometry>
    </collision>

    <xacro:box_inertia m="0.015" w="0.02" h="0.02" d="0.1"/>
  </link>

  <joint name="left_gripper_joint" type="prismatic">
    <axis xyz="0 0 1"/>
    <limit effort="100.0" lower="-0.1" upper="0" velocity="0.25"/>
    <origin xyz="-0.01 0 -0.23" rpy="0 ${pi/2} 0"/>
    <parent link="gripper_pole"/>
    <child link="left_gripper"/>
  </joint>

  <joint name="left_tip_joint" type="fixed">
    <origin rpy="0 -0.2 0" xyz="0.08 0 0"/>
    <parent link="left_gripper"/>
    <child link="left_tip"/>
  </joint>

  <link name="left_tip">
    <visual>
      <geometry>
        <box size="0.06 0.01 0.01"/>
      </geometry>
      <origin rpy="0 0 0" xyz="0 0 0"/>
      <material name="white"/>
    </visual>
    <collision>
      <geometry>
        <box size="0.06 0.01 0.01"/>
      </geometry>
    </collision>

    <xacro:box_inertia m="0.005" w="0.01" h="0.01" d="0.06"/>

  </link>

  <link name="right_gripper">
    <visual>
      <geometry>
        <box size="0.1 0.02 0.02"/>
      </geometry>
      <origin rpy="0 0 0" xyz="0 0 0"/>
      <material name="black"/>
    </visual>
    <collision>
      <geometry>
        <box size="0.1 0.02 0.02"/>
      </geometry>
    </collision>
    <xacro:box_inertia m="0.015" w="0.02" h="0.02" d="0.1"/>
  </link>

  <joint name="right_gripper_joint" type="prismatic">
    <axis xyz="0 0 1"/>
    <limit effort="100.0" lower="0" upper="0.1" velocity="0.25"/>
    <origin rpy="0 ${pi/2} 0" xyz="0.01 0 -0.23"/>
    <parent link="gripper_pole"/>
    <child link="right_gripper"/>
  </joint>


  <link name="right_tip">
    <visual>
      <origin rpy="0 0 0" xyz="0 0 0"/>
      <geometry>
        <box size="0.06 0.01 0.01"/>
      </geometry>
      <material name="white"/>
    </visual>
    <collision>
      <geometry>
        <box size="0.06 0.01 0.01"/>
      </geometry>
    </collision>
    <xacro:box_inertia m="0.005" w="0.01" h="0.01" d="0.06"/>
  </link>

  <joint name="right_tip_joint" type="fixed">
    <origin rpy="0 0.2 0" xyz="0.08 0 0"/>
    <parent link="right_gripper"/>
    <child link="right_tip"/>
  </joint>

<!-- End Robot -->

<!-- IMU -->
<link name="imu_link">
  <visual>
    <geometry>
      <box size="0.05 0.05 0.05"/>
    </geometry>
  </visual>
  <collision>
    <geometry>
      <box size="0.05 0.05 0.05"/>
    </geometry>
  </collision>
  <inertial>
    <origin xyz="0 0 0" rpy="0 0 0"/>
    <mass value="0.1"/>
    <inertia ixx="0.01" ixy="0" ixz="0" iyy="0.01" iyz="0" izz="0.01" />
  </inertial>
</link>

<gazebo reference="imu_link">
    <sensor name="imu_sensor" type="imu">
      <ignition_frame_id>imu_link</ignition_frame_id>
      <plugin filename="ignition-gazebo-imu-system" name="ignition::gazebo::systems::Imu">
      </plugin>

      <topic>imu</topic>
      <always_on>true</always_on>
      <update_rate>50</update_rate>
      <visualize>true</visualize>
      <imu>
        <angular_velocity>
          <x>
            <noise type="gaussian">
              <mean>0.0</mean>
              <stddev>2e-4</stddev>
              <bias_mean>0.0000075</bias_mean>
              <bias_stddev>0.0000008</bias_stddev>
            </noise>
          </x>
          <y>
            <noise type="gaussian">
              <mean>0.0</mean>
              <stddev>2e-4</stddev>
              <bias_mean>0.0000075</bias_mean>
              <bias_stddev>0.0000008</bias_stddev>
            </noise>
          </y>
          <z>
            <noise type="gaussian">
              <mean>0.0</mean>
              <stddev>2e-4</stddev>
              <bias_mean>0.0000075</bias_mean>
              <bias_stddev>0.0000008</bias_stddev>
            </noise>
          </z>
        </angular_velocity>
        <linear_acceleration>
          <x>
            <noise type="gaussian">
              <mean>0.0</mean>
              <stddev>1.7e-2</stddev>
              <bias_mean>0.1</bias_mean>
              <bias_stddev>0.001</bias_stddev>
            </noise>
          </x>
          <y>
            <noise type="gaussian">
              <mean>0.0</mean>
              <stddev>1.7e-2</stddev>
              <bias_mean>0.1</bias_mean>
              <bias_stddev>0.001</bias_stddev>
            </noise>
          </y>
          <z>
            <noise type="gaussian">
              <mean>0.0</mean>
              <stddev>1.7e-2</stddev>
              <bias_mean>0.1</bias_mean>
              <bias_stddev>0.001</bias_stddev>
            </noise>
          </z>
        </linear_acceleration>
      </imu>
    </sensor>
  </gazebo>

<joint name="imu_joint" type="fixed">
  <parent link="base_link"/>
  <child link="imu_link"/>
  <origin xyz="0 0 0.01" rpy="0 0 0"/>
</joint>


<!-- Sistema de controle ROS 2 -->

<ros2_control name="IgnitionSystem" type="system">

  <!-- Seção de hardware do sistema, ponte entre o Gazebo (Ignition) e o ros2_control -->
  <hardware>
    <plugin>ign_ros2_control/IgnitionSystem</plugin>
  </hardware>

  <!-- Definição das rodas -->
  <joint name="base_link_to_wheel_back_right">
    <command_interface name="velocity">
      <param name="min">-1</param>
      <param name="max">1</param>
    </command_interface>
    <state_interface name="position"/>
    <state_interface name="velocity"/>
  </joint>

  <joint name="base_link_to_wheel_back_left">
    <command_interface name="velocity">
      <param name="min">-1</param>
      <param name="max">1</param>
    </command_interface>
    <state_interface name="position"/>
    <state_interface name="velocity"/>
  </joint>

  <joint name="base_link_to_wheel_front_left">
    <command_interface name="velocity">
      <param name="min">-1</param>
      <param name="max">1</param>
    </command_interface>
    <state_interface name="position"/>
    <state_interface name="velocity"/>
  </joint>

  <joint name="base_link_to_wheel_front_right">
    <command_interface name="velocity">
      <param name="min">-1</param>
      <param name="max">1</param>
    </command_interface>
    <state_interface name="position"/>
    <state_interface name="velocity"/>
  </joint>

    <joint name="gripper_extension">
      <command_interface name="position">
        <param name="min">-1.57075</param>
        <param name="max">0.2</param>
      </command_interface>
      <state_interface name="position"/>
      <state_interface name="velocity"/>
    </joint>

    <joint name="left_gripper_joint">
      <command_interface name="position">
        <param name="min">0.0</param>
        <param name="max">0.1</param>
      </command_interface>
      
      <state_interface name="position"/>
      <state_interface name="velocity"/>
    </joint>

    <joint name="right_gripper_joint">
      <command_interface name="position">
        <param name="min">-0.1</param>
        <param name="max">0.0</param>
      </command_interface>

      <state_interface name="position"/>
      <state_interface name="velocity"/>
    </joint>  

  
</ros2_control>

  <gazebo>
    <plugin filename="ign_ros2_control-system" name="ign_ros2_control::IgnitionROS2ControlPlugin">
      <parameters>$(find prm)/config/controller_config.yaml</parameters>
    </plugin>
  </gazebo>

<!-- Sensores -->

<!-- Sensor Lidar -->
<link name="lidar_link">
  <inertial>
    <origin xyz="0 0 0" rpy="0 0 0"/>
    <mass value="0.125"/>
    <inertia ixx="0.001" ixy="0" ixz="0" iyy="0.001" iyz="0" izz="0.001" />
  </inertial>

  <collision>
    <origin xyz="0 0 0" rpy="0 0 0"/>
    <geometry>
        <cylinder radius="0.05" length="0.03"/>
    </geometry>
  </collision>
    
  <visual>
    <origin xyz="0 0 0" rpy="0 0 0"/>  
    <geometry>
      <cylinder radius="0.05" length="0.03"/>
    </geometry>
    <material name="blue"/>
  </visual>
</link>

<joint name="lidar_joint" type="fixed">
  <parent link="base_link"/>
  <child link="lidar_link"/>
  <origin xyz="0 0.1 0" rpy="0 0 1.57"/>
</joint>

<gazebo reference="lidar_link">
  <sensor name="lidar" type="gpu_lidar">
    <ignition_frame_id>lidar_link</ignition_frame_id>
    <topic>scan</topic>
    <always_on>true</always_on>
    <visualize>true</visualize>
    <update_rate>10</update_rate>
    <ray>
      <scan>
          <horizontal>
            <samples>360</samples>
            <resolution>1.000000</resolution>
            <min_angle>0.000000</min_angle>
            <max_angle>6.280000</max_angle>
          </horizontal>
      </scan>
      <range>
          <min>0.120000</min>
          <max>3.5</max>
          <resolution>0.015000</resolution>
      </range>
      <noise>
          <type>gaussian</type>
          <mean>0.0</mean>
          <stddev>0.01</stddev>
      </noise>
    </ray>
  </sensor>
</gazebo>

<!-- Camera -->
<link name="camera_link">
  <visual>
    <geometry>
      <box size="0.02 0.18 0.02"/>
    </geometry>
    <material name="blue"/>
  </visual>
  <collision>
    <geometry>
      <box size="0.02 0.18 0.02"/>
    </geometry>
  </collision>
  
  <inertial>
    <origin xyz="0 0 0" rpy="0 0 0"/>
    <mass value="0.035"/>
    <inertia ixx="0.001" ixy="0" ixz="0" iyy="0.001" iyz="0" izz="0.001" />
  </inertial>
</link>

<joint name="camera_joint" type="fixed">
  <parent link="base_link"/>
  <child link="camera_link"/>
  <origin xyz="0 0.05 0.12" rpy="0 0 1.57"/>
</joint>

<gazebo reference="camera_link">
    <sensor name="robot_cam" type="segmentation">
      <topic>robot_cam</topic>
      <camera>
        <segmentation_type>semantic</segmentation_type>
        <horizontal_fov>1.57</horizontal_fov>
        <image>
          <width>320</width>
          <height>240</height>
        </image>
        <clip>
          <near>0.1</near>
          <far>100</far>
        </clip>
      </camera>
      <always_on>1</always_on>
      <update_rate>15</update_rate>
      <visualize>true</visualize>
    </sensor>
</gazebo>

  <gazebo>
    <plugin filename="libignition-gazebo-pose-publisher-system" name="ignition::gazebo::systems::PosePublisher">
      <publish_link_pose>false</publish_link_pose>
      <publish_model_pose>true</publish_model_pose>
      <publish_nested_model_pose>true</publish_nested_model_pose>
      <use_pose_vector_msg>false</use_pose_vector_msg>
      <publish_visual_pose>false</publish_visual_pose>
      <update_frequency>10</update_frequency>
    </plugin>
  </gazebo>

</robot>